Workbook
Name NativeTimeline_Week_Start_Date1: #N/A
Name Slicer_Content_Type: #N/A
Name Slicer_Platform: #N/A
Name Slicer_Platform1: #N/A
Name Slicer_Week_Start_Date: #N/A

Sheet Posts
A1: Post ID | B1: Platform | C1: Date | D1: Content Type | E1: Post Text | F1: Likes | G1: Shares | H1: Comments | I1: Impressions | J1: Reach | K1: Clicks | L1: Hashtags Used.1 | M1: Hashtags Used.2 | N1: Campaign_Name | O1: ENGAGEMENT RATE | P1: Start_Date | Q1: End_Date | R1: status of cmpign
A2: SP001 | B2: Instagram | C2: 45781 | D2: Text | E2: Discover fresh beats on Spotify! | F2: 2414 | G2: 245 | H2: 137 | I2: 21181 | J2: 45292 | K2: 133 | L2: #SoundtrackOfLife | M2: #NowPlaying | N2: ChillVibes | O2: =(F2+G2+H2)/I2 -> 0.1320051 | P2: =(_xlfn.XLOOKUP(Table1__3[[#This Row],[Campaign_Name]],Table3[Campaign_Name],Table3[Start_Date])) -> 45667 | Q2: =(_xlfn.XLOOKUP(Table1__3[[#This Row],[Campaign_Name]],Table3[Campaign_Name],Table3[End_Date])) -> 45698 | R2: =IF(Table1__3[[#This Row],[Date]] < Table1__3[[#This Row],[Start_Date]], "Before", IF(AND(Table1__3[[#This Row],[Date]] >= Table1__3[[#This Row],[Start_Date]], Table1__3[[#This Row],[Date]] <= Table1__3[[#This Row],[End_Date]]), "During", "After")) -> After
A3: SP002 | B3: Instagram | C3: 45689 | D3: Text | E3: Explore the latest podcasts now. | F3: 1934 | G3: 210 | H3: 393 | I3: 29129 | J3: 73287 | K3: 273 | L3: #DiscoverWeekly | N3: IndieWave | O3: =(F3+G3+H3)/I3 -> 0.087095335 | P3: =(_xlfn.XLOOKUP(Table1__3[[#This Row],[Campaign_Name]],Table3[Campaign_Name],Table3[Start_Date])) -> 45717 | Q3: =(_xlfn.XLOOKUP(Table1__3[[#This Row],[Campaign_Name]],Table3[Campaign_Name],Table3[End_Date])) -> 45747 | R3: =IF(Table1__3[[#This Row],[Date]] < Table1__3[[#This Row],[Start_Date]], "Before", IF(AND(Table1__3[[#This Row],[Date]] >= Table1__3[[#This Row],[Start_Date]], Table1__3[[#This Row],[Date]] <= Table1__3[[#This Row],[End_Date]]), "During", "After")) -> Before
A4: SP003 | B4: Twitter | C4: 45629 | D4: Story | E4: New music just dropped. Hit play! | F4: 3092 | G4: 177 | H4: 81 | I4: 47533 | J4: 29220 | K4: 121 | L4: #MusicForEveryone | M4: #NowPlaying | N4: ChillVibes | O4: =(F4+G4+H4)/I4 -> 0.070477353 | P4: =(_xlfn.XLOOKUP(Table1__3[[#This Row],[Campaign_Name]],Table3[Campaign_Name],Table3[Start_Date])) -> 45667 | Q4: =(_xlfn.XLOOKUP(Table1__3[[#This Row],[Campaign_Name]],Table3[Campaign_Name],Table3[End_Date])) -> 45698 | R4: =IF(Table1__3[[#This Row],[Date]] < Table1__3[[#This Row],[Start_Date]], "Before", IF(AND(Table1__3[[#This Row],[Date]] >= Table1__3[[#This Row],[Start_Date]], Table1__3[[#This Row],[Date]] <= Table1__3[[#This Row],[End_Date]]), "During", "After")) -> Before
A5: SP004 | B5: Instagram | C5: 45629 | D5: Text | E5: Wrapped is here! Relive your top tracks ðŸŽ§ | F5: 3173 | G5: 229 | H5: 197 | I5: 29604 | J5: 21809 | K5: 272 | L5: #SoundtrackOfLife | M5: #NowPlaying | N5: ChillVibes | O5: =(F5+G5+H5)/I5 -> 0.12157141 | P5: =(_xlfn.XLOOKUP(Table1__3[[#This Row],[Campaign_Name]],Table3[Campaign_Name],Table3[Start_Date])) -> 45667 | Q5: =(_xlfn.XLOOKUP(Table1__3[[#This Row],[Campaign_Name]],Table3[Campaign_Name],Table3[End_Date])) -> 45698 | R5: =IF(Table1__3[[#This Row],[Date]] < Table1__3[[#This Row],[Start_Date]], "Before", IF(AND(Table1__3[[#This Row],[Date]] >= Table1__3[[#This Row],[Start_Date]], Table1__3[[#This Row],[Date]] <= Table1__3[[#This Row],[End_Date]]), "During", "After")) -> Before
A6: SP005 | B6: YouTube | C6: 45388 | D6: Text | E6: Music that moves youâ€”only on Spotify. | F6: 2748 | G6: 145 | H6: 315 | I6: 24401 | J6: 61182 | K6: 200 | L6: #DiscoverWeekly | M6: #SpotifyWrapped | N6: IndieWave | O6: =(F6+G6+H6)/I6 -> 0.13147002 | P6: =(_xlfn.XLOOKUP(Table1__3[[#This Row],[Campaign_Name]],Table3[Campaign_Name],Table3[Start_Date])) -> 45717 | Q6: =(_xlfn.XLOOKUP(Table1__3[[#This Row],[Campaign_Name]],Table3[Campaign_Name],Table3[End_Date])) -> 45747 | R6: =IF(Table1__3[[#This Row],[Date]] < Table1__3[[#This Row],[Start_Date]], "Before", IF(AND(Table1__3[[#This Row],[Date]] >= Table1__3[[#This Row],[Start_Date]], Table1__3[[#This Row],[Date]] <= Table1__3[[#This Row],[End_Date]]), "During", "After")) -> Before
A7: SP006 | B7: YouTube | C7: 45456 | D7: Text | E7: Whatâ€™s your vibe today? #SpotifyHits | F7: 3882 | G7: 239 | H7: 275 | I7: 58748 | J7: 44646 | K7: 149 | L7: #DiscoverWeekly | M7: #SpotifyWrapped | N7: IndieWave | O7: =(F7+G7+H7)/I7 -> 0.074828079 | P7: =(_xlfn.XLOOKUP(Table1__3[[#This Row],[Campaign_Name]],Table3[Campaign_Name],Table3[Start_Date])) -> 45717 | Q7: =(_xlfn.XLOOKUP(Table1__3[[#This Row],[Campaign_Name]],Table3[Campaign_Name],Table3[End_Date])) -> 45747 | R7: =IF(Table1__3[[#This Row],[Date]] < Table1__3[[#This Row],[Start_Date]], "Before", IF(AND(Table1__3[[#This Row],[Date]] >= Table1__3[[#This Row],[Start_Date]], Table1__3[[#This Row],[Date]] <= Table1__3[[#This Row],[End_Date]]), "During", "After")) -> Before
A8: SP007 | B8: Twitter | C8: 45645 | D8: Story | E8: Get into the groove with our new drop! | F8: 4674 | G8: 409 | H8: 327 | I8: 20756 | J8: 63599 | K8: 212 | L8: #SoundtrackOfLife | M8: #NowPlaying | N8: ChillVibes | O8: =(F8+G8+H8)/I8 -> 0.26064752 | P8: =(_xlfn.XLOOKUP(Table1__3[[#This Row],[Campaign_Name]],Table3[Campaign_Name],Table3[Start_Date])) -> 45667 | Q8: =(_xlfn.XLOOKUP(Table1__3[[#This Row],[Campaign_Name]],Table3[Campaign_Name],Table3[End_Date])) -> 45698 | R8: =IF(Table1__3[[#This Row],[Date]] < Table1__3[[#This Row],[Start_Date]], "Before", IF(AND(Table1__3[[#This Row],[Date]] >= Table1__3[[#This Row],[Start_Date]], Table1__3[[#This Row],[Date]] <= Table1__3[[#This Row],[End_Date]]), "During", "After")) -> Before
A9: SP008 | B9: Twitter | C9: 45421 | D9: Story | E9: Wrapped is here! Relive your top tracks ðŸŽ§ | F9: 1428 | G9: 347 | H9: 67 | I9: 21148 | J9: 19712 | K9: 120 | L9: #DiscoverWeekly | M9: #MusicForEveryone | N9: ChillVibes | O9: =(F9+G9+H9)/I9 -> 0.087100435 | P9: =(_xlfn.XLOOKUP(Table1__3[[#This Row],[Campaign_Name]],Table3[Campaign_Name],Table3[Start_Date])) -> 45667 | Q9: =(_xlfn.XLOOKUP(Table1__3[[#This Row],[Campaign_Name]],Table3[Campaign_Name],Table3[End_Date])) -> 45698 | R9: =IF(Table1__3[[#This Row],[Date]] < Table1__3[[#This Row],[Start_Date]], "Before", IF(AND(Table1__3[[#This Row],[Date]] >= Table1__3[[#This Row],[Start_Date]], Table1__3[[#This Row],[Date]] <= Table1__3[[#This Row],[End_Date]]), "During", "After")) -> Before
A10: SP009 | B10: Twitter | C10: 45823 | D10: Text | E10: Top trending tracks updated daily! | F10: 4432 | G10: 223 | H10: 299 | I10: 59016 | J10: 21742 | K10: 171 | L10: #NowPlaying | N10: ChillVibes | O10: =(F10+G10+H10)/I10 -> 0.083943337 | P10: =(_xlfn.XLOOKUP(Table1__3[[#This Row],[Campaign_Name]],Table3[Campaign_Name],Table3[Start_Date])) -> 45667 | Q10: =(_xlfn.XLOOKUP(Table1__3[[#This Row],[Campaign_Name]],Table3[Campaign_Name],Table3[End_Date])) -> 45698 | R10: =IF(Table1__3[[#This Row],[Date]] < Table1__3[[#This Row],[Start_Date]], "Before", IF(AND(Table1__3[[#This Row],[Date]] >= Table1__3[[#This Row],[Start_Date]], Table1__3[[#This Row],[Date]] <= Table1__3[[#This Row],[End_Date]]), "During", "After")) -> After
A11: SP010 | B11: Twitter | C11: 45630 | D11: Text | E11: Wrapped is here! Relive your top tracks ðŸŽ§ | F11: 2357 | G11: 274 | H11: 172 | I11: 21566 | J11: 66829 | K11: 284 | L11: #NowPlaying | N11: ChillVibes | O11: =(F11+G11+H11)/I11 -> 0.12997311 | P11: =(_xlfn.XLOOKUP(Table1__3[[#This Row],[Campaign_Name]],Table3[Campaign_Name],Table3[Start_Date])) -> 45667 | Q11: =(_xlfn.XLOOKUP(Table1__3[[#This Row],[Campaign_Name]],Table3[Campaign_Name],Table3[End_Date])) -> 45698 | R11: =IF(Table1__3[[#This Row],[Date]] < Table1__3[[#This Row],[Start_Date]], "Before", IF(AND(Table1__3[[#This Row],[Date]] >= Table1__3[[#This Row],[Start_Date]], Table1__3[[#This Row],[Date]] <= Table1__3[[#This Row],[End_Date]]), "During", "After")) -> Before
A12: SP011 | B12: Twitter | C12: 45357 | D12: Text | E12: Discover fresh beats on Spotify! | F12: 1971 | G12: 370 | H12: 306 | I12: 31316 | J12: 27897 | K12: 88 | L12: #SoundtrackOfLife | N12: IndieWave | O12: =(F12+G12+H12)/I12 -> 0.084525482 | P12: =(_xlfn.XLOOKUP(Table1__3[[#This Row],[Campaign_Name]],Table3[Campaign_Name],Table3[Start_Date])) -> 45717 | Q12: =(_xlfn.XLOOKUP(Table1__3[[#This Row],[Campaign_Name]],Table3[Campaign_Name],Table3[End_Date])) -> 45747 | R12: =IF(Table1__3[[#This Row],[Date]] < Table1__3[[#This Row],[Start_Date]], "Before", IF(AND(Table1__3[[#This Row],[Date]] >= Table1__3[[#This Row],[Start_Date]], Table1__3[[#This Row],[Date]] <= Table1__3[[#This Row],[End_Date]]), "During", "After")) -> Before
A13: SP012 | B13: Instagram | C13: 45426 | D13: Text | E13: Discover fresh beats on Spotify! | F13: 1485 | G13: 353 | H13: 244 | I13: 38419 | J13: 38556 | K13: 86 | L13: #SoundtrackOfLife | M13: #NowPlaying | N13: ChillVibes | O13: =(F13+G13+H13)/I13 -> 0.054191936 | P13: =(_xlfn.XLOOKUP(Table1__3[[#This Row],[Campaign_Name]],Table3[Campaign_Name],Table3[Start_Date])) -> 45667 | Q13: =(_xlfn.XLOOKUP(Table1__3[[#This Row],[Campaign_Name]],Table3[Campaign_Name],Table3[End_Date])) -> 45698 | R13: =IF(Table1__3[[#This Row],[Date]] < Table1__3[[#This Row],[Start_Date]], "Before", IF(AND(Table1__3[[#This Row],[Date]] >= Table1__3[[#This Row],[Start_Date]], Table1__3[[#This Row],[Date]] <= Table1__3[[#This Row],[End_Date]]), "During", "After")) -> Before
A14: SP013 | B14: Twitter | C14: 45826 | D14: Story | E14: Discover fresh beats on Spotify! | F14: 3956 | G14: 319 | H14: 61 | I14: 58162 | J14: 28720 | K14: 213 | L14: #MusicForEveryone | M14: #NowPlaying | N14: ChillVibes | O14: =(F14+G14+H14)/I14 -> 0.074550394 | P14: =(_xlfn.XLOOKUP(Table1__3[[#This Row],[Campaign_Name]],Table3[Campaign_Name],Table3[Start_Date])) -> 45667 | Q14: =(_xlfn.XLOOKUP(Table1__3[[#This Row],[Campaign_Name]],Table3[Campaign_Name],Table3[End_Date])) -> 45698 | R14: =IF(Table1__3[[#This Row],[Date]] < Table1__3[[#This Row],[Start_Date]], "Before", IF(AND(Table1__3[[#This Row],[Date]] >= Table1__3[[#This Row],[Start_Date]], Table1__3[[#This Row],[Date]] <= Table1__3[[#This Row],[End_Date]]), "During", "After")) -> After
A15: SP014 | B15: Twitter | C15: 45573 | D15: Text | E15: From pop to podcasts, itâ€™s all here. | F15: 2460 | G15: 409 | H15: 253 | I15: 36702 | J15: 46122 | K15: 264 | L15: #NowPlaying | N15: ChillVibes | O15: =(F15+G15+H15)/I15 -> 0.085063484 | P15: =(_xlfn.XLOOKUP(Table1__3[[#This Row],[Campaign_Name]],Table3[Campaign_Name],Table3[Start_Date])) -> 45667 | Q15: =(_xlfn.XLOOKUP(Table1__3[[#This Row],[Campaign_Name]],Table3[Campaign_Name],Table3[End_Date])) -> 45698 | R15: =IF(Table1__3[[#This Row],[Date]] < Table1__3[[#This Row],[Start_Date]], "Before", IF(AND(Table1__3[[#This Row],[Date]] >= Table1__3[[#This Row],[Start_Date]], Table1__3[[#This Row],[Date]] <= Table1__3[[#This Row],[End_Date]]), "During", "After")) -> Before
A16: SP015 | B16: Twitter | C16: 45418 | D16: Text | E16: Your weekend playlist is waiting. | F16: 3476 | G16: 355 | H16: 396 | I16: 37492 | J16: 27285 | K16: 179 | L16: #NowPlaying | N16: ChillVibes | O16: =(F16+G16+H16)/I16 -> 0.11274405 | P16: =(_xlfn.XLOOKUP(Table1__3[[#This Row],[Campaign_Name]],Table3[Campaign_Name],Table3[Start_Date])) -> 45667 | Q16: =(_xlfn.XLOOKUP(Table1__3[[#This Row],[Campaign_Name]],Table3[Campaign_Name],Table3[End_Date])) -> 45698 | R16: =IF(Table1__3[[#This Row],[Date]] < Table1__3[[#This Row],[Start_Date]], "Before", IF(AND(Table1__3[[#This Row],[Date]] >= Table1__3[[#This Row],[Start_Date]], Table1__3[[#This Row],[Date]] <= Table1__3[[#This Row],[End_Date]]), "During", "After")) -> Before
A17: SP016 | B17: Twitter | C17: 45655 | D17: Story | E17: New music just dropped. Hit play! | F17: 4049 | G17: 377 | H17: 94 | I17: 48182 | J17: 42875 | K17: 172 | L17: #MusicForEveryone | M17: #NowPlaying | N17: ChillVibes | O17: =(F17+G17+H17)/I17 -> 0.093810967 | P17: =(_xlfn.XLOOKUP(Table1__3[[#This Row],[Campaign_Name]],Table3[Campaign_Name],Table3[Start_Date])) -> 45667 | Q17: =(_xlfn.XLOOKUP(Table1__3[[#This Row],[Campaign_Name]],Table3[Campaign_Name],Table3[End_Date])) -> 45698 | R17: =IF(Table1__3[[#This Row],[Date]] < Table1__3[[#This Row],[Start_Date]], "Before", IF(AND(Table1__3[[#This Row],[Date]] >= Table1__3[[#This Row],[Start_Date]], Table1__3[[#This Row],[Date]] <= Table1__3[[#This Row],[End_Date]]), "During", "After")) -> Before
A18: SP017 | B18: Twitter | C18: 45453 | D18: Text | E18: Whatâ€™s your vibe today? #SpotifyHits | F18: 1514 | G18: 164 | H18: 275 | I18: 41364 | J18: 44389 | K18: 83 | L18: #NowPlaying | N18: ChillVibes | O18: =(F18+G18+H18)/I18 -> 0.04721497 | P18: =(_xlfn.XLOOKUP(Table1__3[[#This Row],[Campaign_Name]],Table3[Campaign_Name],Table3[Start_Date])) -> 45667 | Q18: =(_xlfn.XLOOKUP(Table1__3[[#This Row],[Campaign_Name]],Table3[Campaign_Name],Table3[End_Date])) -> 45698 | R18: =IF(Table1__3[[#This Row],[Date]] < Table1__3[[#This Row],[Start_Date]], "Before", IF(AND(Table1__3[[#This Row],[Date]] >= Table1__3[[#This Row],[Start_Date]], Table1__3[[#This Row],[Date]] <= Table1__3[[#This Row],[End_Date]]), "During", "After")) -> Before
A19: SP018 | B19: Instagram | C19: 45325 | D19: Story | E19: Music that moves youâ€”only on Spotify. | F19: 4281 | G19: 101 | H19: 163 | I19: 32278 | J19: 53382 | K19: 235 | L19: #NowPlaying | N19: Wrapped2024 | O19: =(F19+G19+H19)/I19 -> 0.14080798 | P19: =(_xlfn.XLOOKUP(Table1__3[[#This Row],[Campaign_Name]],Table3[Campaign_Name],Table3[Start_Date])) -> 45627 | Q19: =(_xlfn.XLOOKUP(Table1__3[[#This Row],[Campaign_Name]],Table3[Campaign_Name],Table3[End_Date])) -> 45657 | R19: =IF(Table1__3[[#This Row],[Date]] < Table1__3[[#This Row],[Start_Date]], "Before", IF(AND(Table1__3[[#This Row],[Date]] >= Table1__3[[#This Row],[Start_Date]], Table1__3[[#This Row],[Date]] <= Table1__3[[#This Row],[End_Date]]), "During", "After")) -> Before
A20: SP019 | B20: YouTube | C20: 45458 | D20: Reel | E20: Get into the groove with our new drop! | F20: 1751 | G20: 143 | H20: 151 | I20: 31826 | J20: 47729 | K20: 95 | L20: #DiscoverWeekly | M20: #SoundtrackOfLife | N20: SummerBeats | O20: =(F20+G20+H20)/I20 -> 0.06425564 | P20: =(_xlfn.XLOOKUP(Table1__3[[#This Row],[Campaign_Name]],Table3[Campaign_Name],Table3[Start_Date])) -> 45458 | Q20: =(_xlfn.XLOOKUP(Table1__3[[#This Row],[Campaign_Name]],Table3[Campaign_Name],Table3[End_Date])) -> 45488 | R20: =IF(Table1__3[[#This Row],[Date]] < Table1__3[[#This Row],[Start_Date]], "Before", IF(AND(Table1__3[[#This Row],[Date]] >= Table1__3[[#This Row],[Start_Date]], Table1__3[[#This Row],[Date]] <= Table1__3[[#This Row],[End_Date]]), "During", "After")) -> During
A21: SP020 | B21: Instagram | C21: 45478 | D21: Text | E21: Your weekend playlist is waiting. | F21: 3753 | G21: 411 | H21: 308 | I21: 29138 | J21: 27678 | K21: 90 | L21: #DiscoverWeekly | N21: IndieWave | O21: =(F21+G21+H21)/I21 -> 0.15347656 | P21: =(_xlfn.XLOOKUP(Table1__3[[#This Row],[Campaign_Name]],Table3[Campaign_Name],Table3[Start_Date])) -> 45717 | Q21: =(_xlfn.XLOOKUP(Table1__3[[#This Row],[Campaign_Name]],Table3[Campaign_Name],Table3[End_Date])) -> 45747 | R21: =IF(Table1__3[[#This Row],[Date]] < Table1__3[[#This Row],[Start_Date]], "Before", IF(AND(Table1__3[[#This Row],[Date]] >= Table1__3[[#This Row],[Start_Date]], Table1__3[[#This Row],[Date]] <= Table1__3[[#This Row],[End_Date]]), "During", "After")) -> Before
A22: SP021 | B22: Instagram | C22: 45603 | D22: Story | E22: Wrapped is here! Relive your top tracks ðŸŽ§ | F22: 1678 | G22: 423 | H22: 323 | I22: 55668 | J22: 37945 | K22: 230 | L22: #NowPlaying | N22: Wrapped2024 | O22: =(F22+G22+H22)/I22 -> 0.043543867 | P22: =(_xlfn.XLOOKUP(Table1__3[[#This Row],[Campaign_Name]],Table3[Campaign_Name],Table3[Start_Date])) -> 45627 | Q22: =(_xlfn.XLOOKUP(Table1__3[[#This Row],[Campaign_Name]],Table3[Campaign_Name],Table3[End_Date])) -> 45657 | R22: =IF(Table1__3[[#This Row],[Date]] < Table1__3[[#This Row],[Start_Date]], "Before", IF(AND(Table1__3[[#This Row],[Date]] >= Table1__3[[#This Row],[Start_Date]], Table1__3[[#This Row],[Date]] <= Table1__3[[#This Row],[End_Date]]), "During", "After")) -> Before
A23: SP022 | B23: Instagram | C23: 45823 | D23: Text | E23: Whatâ€™s your vibe today? #SpotifyHits | F23: 4896 | G23: 466 | H23: 233 | I23: 28621 | J23: 34270 | K23: 84 | L23: #SoundtrackOfLife | M23: #NowPlaying | N23: ChillVibes | O23: =(F23+G23+H23)/I23 -> 0.19548583 | P23: =(_xlfn.XLOOKUP(Table1__3[[#This Row],[Campaign_Name]],Table3[Campaign_Name],Table3[Start_Date])) -> 45667 | Q23: =(_xlfn.XLOOKUP(Table1__3[[#This Row],[Campaign_Name]],Table3[Campaign_Name],Table3[End_Date])) -> 45698 | R23: =IF(Table1__3[[#This Row],[Date]] < Table1__3[[#This Row],[Start_Date]], "Before", IF(AND(Table1__3[[#This Row],[Date]] >= Table1__3[[#This Row],[Start_Date]], Table1__3[[#This Row],[Date]] <= Table1__3[[#This Row],[End_Date]]), "During", "After")) -> After
A24: SP023 | B24: YouTube | C24: 45452 | D24: Reel | E24: From pop to podcasts, itâ€™s all here. | F24: 2786 | G24: 368 | H24: 208 | I24: 42000 | J24: 39967 | K24: 103 | L24: #DiscoverWeekly | M24: #SoundtrackOfLife | N24: SummerBeats | O24: =(F24+G24+H24)/I24 -> 0.080047619 | P24: =(_xlfn.XLOOKUP(Table1__3[[#This Row],[Campaign_Name]],Table3[Campaign_Name],Table3[Start_Date])) -> 45458 | Q24: =(_xlfn.XLOOKUP(Table1__3[[#This Row],[Campaign_Name]],Table3[Campaign_Name],Table3[End_Date])) -> 45488 | R24: =IF(Table1__3[[#This Row],[Date]] < Table1__3[[#This Row],[Start_Date]], "Before", IF(AND(Table1__3[[#This Row],[Date]] >= Table1__3[[#This Row],[Start_Date]], Table1__3[[#This Row],[Date]] <= Table1__3[[#This Row],[End_Date]]), "During", "After")) -> Before
A25: SP024 | B25: Twitter | C25: 45583 | D25: Text | E25: New music just dropped. Hit play! | F25: 2607 | G25: 379 | H25: 180 | I25: 28712 | J25: 61620 | K25: 174 | L25: #SoundtrackOfLife | N25: IndieWave | O25: =(F25+G25+H25)/I25 -> 0.11026748 | P25: =(_xlfn.XLOOKUP(Table1__3[[#This Row],[Campaign_Name]],Table3[Campaign_Name],Table3[Start_Date])) -> 45717 | Q25: =(_xlfn.XLOOKUP(Table1__3[[#This Row],[Campaign_Name]],Table3[Campaign_Name],Table3[End_Date])) -> 45747 | R25: =IF(Table1__3[[#This Row],[Date]] < Table1__3[[#This Row],[Start_Date]], "Before", IF(AND(Table1__3[[#This Row],[Date]] >= Table1__3[[#This Row],[Start_Date]], Table1__3[[#This Row],[Date]] <= Table1__3[[#This Row],[End_Date]]), "During", "After")) -> Before
A26: SP025 | B26: YouTube | C26: 45575 | D26: Reel | E26: From pop to podcasts, itâ€™s all here. | F26: 4013 | G26: 320 | H26: 92 | I26: 54605 | J26: 60169 | K26: 232 | L26: #DiscoverWeekly | M26: #SoundtrackOfLife | N26: SummerBeats | O26: =(F26+G26+H26)/I26 -> 0.081036535 | P26: =(_xlfn.XLOOKUP(Table1__3[[#This Row],[Campaign_Name]],Table3[Campaign_Name],Table3[Start_Date])) -> 45458 | Q26: =(_xlfn.XLOOKUP(Table1__3[[#This Row],[Campaign_Name]],Table3[Campaign_Name],Table3[End_Date])) -> 45488 | R26: =IF(Table1__3[[#This Row],[Date]] < Table1__3[[#This Row],[Start_Date]], "Before", IF(AND(Table1__3[[#This Row],[Date]] >= Table1__3[[#This Row],[Start_Date]], Table1__3[[#This Row],[Date]] <= Table1__3[[#This Row],[End_Date]]), "During", "After")) -> After
A27: SP026 | B27: Twitter | C27: 45791 | D27: Story | E27: From pop to podcasts, itâ€™s all here. | F27: 2707 | G27: 103 | H27: 51 | I27: 55302 | J27: 18801 | K27: 147 | L27: #DiscoverWeekly | M27: #MusicForEveryone | N27: ChillVibes | O27: =(F27+G27+H27)/I27 -> 0.051734114 | P27: =(_xlfn.XLOOKUP(Table1__3[[#This Row],[Campaign_Name]],Table3[Campaign_Name],Table3[Start_Date])) -> 45667 | Q27: =(_xlfn.XLOOKUP(Table1__3[[#This Row],[Campaign_Name]],Table3[Campaign_Name],Table3[End_Date])) -> 45698 | R27: =IF(Table1__3[[#This Row],[Date]] < Table1__3[[#This Row],[Start_Date]], "Before", IF(AND(Table1__3[[#This Row],[Date]] >= Table1__3[[#This Row],[Start_Date]], Table1__3[[#This Row],[Date]] <= Table1__3[[#This Row],[End_Date]]), "During", "After")) -> After
A28: SP027 | B28: Instagram | C28: 45625 | D28: Text | E28: Whatâ€™s your vibe today? #SpotifyHits | F28: 2824 | G28: 425 | H28: 274 | I28: 31004 | J28: 53488 | K28: 268 | L28: #SoundtrackOfLife | M28: #NowPlaying | N28: ChillVibes | O28: =(F28+G28+H28)/I28 -> 0.1136305 | P28: =(_xlfn.XLOOKUP(Table1__3[[#This Row],[Campaign_Name]],Table3[Campaign_Name],Table3[Start_Date])) -> 45667 | Q28: =(_xlfn.XLOOKUP(Table1__3[[#This Row],[Campaign_Name]],Table3[Campaign_Name],Table3[End_Date])) -> 45698 | R28: =IF(Table1__3[[#This Row],[Date]] < Table1__3[[#This Row],[Start_Date]], "Before", IF(AND(Table1__3[[#This Row],[Date]] >= Table1__3[[#This Row],[Start_Date]], Table1__3[[#This Row],[Date]] <= Table1__3[[#This Row],[End_Date]]), "During", "After")) -> Before
A29: SP028 | B29: YouTube | C29: 45356 | D29: Reel | E29: Explore the latest podcasts now. | F29: 3558 | G29: 314 | H29: 199 | I29: 49612 | J29: 53929 | K29: 206 | L29: #DiscoverWeekly | M29: #SoundtrackOfLife | N29: SummerBeats | O29: =(F29+G29+H29)/I29 -> 0.08205676 | P29: =(_xlfn.XLOOKUP(Table1__3[[#This Row],[Campaign_Name]],Table3[Campaign_Name],Table3[Start_Date])) -> 45458 | Q29: =(_xlfn.XLOOKUP(Table1__3[[#This Row],[Campaign_Name]],Table3[Campaign_Name],Table3[End_Date])) -> 45488 | R29: =IF(Table1__3[[#This Row],[Date]] < Table1__3[[#This Row],[Start_Date]], "Before", IF(AND(Table1__3[[#This Row],[Date]] >= Table1__3[[#This Row],[Start_Date]], Table1__3[[#This Row],[Date]] <= Table1__3[[#This Row],[End_Date]]), "During", "After")) -> Before
A30: SP029 | B30: Twitter | C30: 45734 | D30: Story | E30: Explore the latest podcasts now. | F30: 3418 | G30: 188 | H30: 387 | I30: 57431 | J30: 36933 | K30: 202 | L30: #MusicForEveryone | M30: #NowPlaying | N30: ChillVibes | O30: =(F30+G30+H30)/I30 -> 0.069526911 | P30: =(_xlfn.XLOOKUP(Table1__3[[#This Row],[Campaign_Name]],Table3[Campaign_Name],Table3[Start_Date])) -> 45667 | Q30: =(_xlfn.XLOOKUP(Table1__3[[#This Row],[Campaign_Name]],Table3[Campaign_Name],Table3[End_Date])) -> 45698 | R30: =IF(Table1__3[[#This Row],[Date]] < Table1__3[[#This Row],[Start_Date]], "Before", IF(AND(Table1__3[[#This Row],[Date]] >= Table1__3[[#This Row],[Start_Date]], Table1__3[[#This Row],[Date]] <= Table1__3[[#This Row],[End_Date]]), "During", "After")) -> After
A31: SP030 | B31: Twitter | C31: 45773 | D31: Text | E31: Discover fresh beats on Spotify! | F31: 2411 | G31: 194 | H31: 168 | I31: 26665 | J31: 71699 | K31: 197 | L31: #NowPlaying | N31: ChillVibes | O31: =(F31+G31+H31)/I31 -> 0.103994 | P31: =(_xlfn.XLOOKUP(Table1__3[[#This Row],[Campaign_Name]],Table3[Campaign_Name],Table3[Start_Date])) -> 45667 | Q31: =(_xlfn.XLOOKUP(Table1__3[[#This Row],[Campaign_Name]],Table3[Campaign_Name],Table3[End_Date])) -> 45698 | R31: =IF(Table1__3[[#This Row],[Date]] < Table1__3[[#This Row],[Start_Date]], "Before", IF(AND(Table1__3[[#This Row],[Date]] >= Table1__3[[#This Row],[Start_Date]], Table1__3[[#This Row],[Date]] <= Table1__3[[#This Row],[End_Date]]), "During", "After")) -> After
A32: SP031 | B32: Instagram | C32: 45658 | D32: Text | E32: New music just dropped. Hit play! | F32: 4036 | G32: 112 | H32: 382 | I32: 56284 | J32: 29440 | K32: 279 | L32: #SoundtrackOfLife | M32: #NowPlaying | N32: ChillVibes | O32: =(F32+G32+H32)/I32 -> 0.080484685 | P32: =(_xlfn.XLOOKUP(Table1__3[[#This Row],[Campaign_Name]],Table3[Campaign_Name],Table3[Start_Date])) -> 45667 | Q32: =(_xlfn.XLOOKUP(Table1__3[[#This Row],[Campaign_Name]],Table3[Campaign_Name],Table3[End_Date])) -> 45698 | R32: =IF(Table1__3[[#This Row],[Date]] < Table1__3[[#This Row],[Start_Date]], "Before", IF(AND(Table1__3[[#This Row],[Date]] >= Table1__3[[#This Row],[Start_Date]], Table1__3[[#This Row],[Date]] <= Table1__3[[#This Row],[End_Date]]), "During", "After")) -> Before
A33: SP032 | B33: Twitter | C33: 45419 | D33: Story | E33: Explore the latest podcasts now. | F33: 2776 | G33: 307 | H33: 178 | I33: 43365 | J33: 48408 | K33: 138 | L33: #SoundtrackOfLife | M33: #NowPlaying | N33: ChillVibes | O33: =(F33+G33+H33)/I33 -> 0.075198893 | P33: =(_xlfn.XLOOKUP(Table1__3[[#This Row],[Campaign_Name]],Table3[Campaign_Name],Table3[Start_Date])) -> 45667 | Q33: =(_xlfn.XLOOKUP(Table1__3[[#This Row],[Campaign_Name]],Table3[Campaign_Name],Table3[End_Date])) -> 45698 | R33: =IF(Table1__3[[#This Row],[Date]] < Table1__3[[#This Row],[Start_Date]], "Before", IF(AND(Table1__3[[#This Row],[Date]] >= Table1__3[[#This Row],[Start_Date]], Table1__3[[#This Row],[Date]] <= Table1__3[[#This Row],[End_Date]]), "During", "After")) -> Before
A34: SP033 | B34: Twitter | C34: 45574 | D34: Story | E34: Discover fresh beats on Spotify! | F34: 4929 | G34: 182 | H34: 95 | I34: 32181 | J34: 31084 | K34: 289 | L34: #DiscoverWeekly | M34: #MusicForEveryone | N34: ChillVibes | O34: =(F34+G34+H34)/I34 -> 0.16177247 | P34: =(_xlfn.XLOOKUP(Table1__3[[#This Row],[Campaign_Name]],Table3[Campaign_Name],Table3[Start_Date])) -> 45667 | Q34: =(_xlfn.XLOOKUP(Table1__3[[#This Row],[Campaign_Name]],Table3[Campaign_Name],Table3[End_Date])) -> 45698 | R34: =IF(Table1__3[[#This Row],[Date]] < Table1__3[[#This Row],[Start_Date]], "Before", IF(AND(Table1__3[[#This Row],[Date]] >= Table1__3[[#This Row],[Start_Date]], Table1__3[[#This Row],[Date]] <= Table1__3[[#This Row],[End_Date]]), "During", "After")) -> Before
A35: SP034 | B35: Instagram | C35: 45666 | D35: Text | E35: New music just dropped. Hit play! | F35: 1015 | G35: 366 | H35: 308 | I35: 38127 | J35: 63790 | K35: 287 | L35: #SoundtrackOfLife | M35: #NowPlaying | N35: ChillVibes | O35: =(F35+G35+H35)/I35 -> 0.044299315 | P35: =(_xlfn.XLOOKUP(Table1__3[[#This Row],[Campaign_Name]],Table3[Campaign_Name],Table3[Start_Date])) -> 45667 | Q35: =(_xlfn.XLOOKUP(Table1__3[[#This Row],[Campaign_Name]],Table3[Campaign_Name],Table3[End_Date])) -> 45698 | R35: =IF(Table1__3[[#This Row],[Date]] < Table1__3[[#This Row],[Start_Date]], "Before", IF(AND(Table1__3[[#This Row],[Date]] >= Table1__3[[#This Row],[Start_Date]], Table1__3[[#This Row],[Date]] <= Table1__3[[#This Row],[End_Date]]), "During", "After")) -> Before
A36: SP035 | B36: Twitter | C36: 45785 | D36: Story | E36: Your weekend playlist is waiting. | F36: 3316 | G36: 332 | H36: 268 | I36: 40095 | J36: 36913 | K36: 265 | L36: #MusicForEveryone | M36: #NowPlaying | N36: ChillVibes | O36: =(F36+G36+H36)/I36 -> 0.097668038 | P36: =(_xlfn.XLOOKUP(Table1__3[[#This Row],[Campaign_Name]],Table3[Campaign_Name],Table3[Start_Date])) -> 45667 | Q36: =(_xlfn.XLOOKUP(Table1__3[[#This Row],[Campaign_Name]],Table3[Campaign_Name],Table3[End_Date])) -> 45698 | R36: =IF(Table1__3[[#This Row],[Date]] < Table1__3[[#This Row],[Start_Date]], "Before", IF(AND(Table1__3[[#This Row],[Date]] >= Table1__3[[#This Row],[Start_Date]], Table1__3[[#This Row],[Date]] <= Table1__3[[#This Row],[End_Date]]), "During", "After")) -> After
A37: SP036 | B37: Instagram | C37: 45416 | D37: Text | E37: Wrapped is here! Relive your top tracks ðŸŽ§ | F37: 2274 | G37: 243 | H37: 222 | I37: 43066 | J37: 59174 | K37: 80 | L37: #DiscoverWeekly | N37: IndieWave | O37: =(F37+G37+H37)/I37 -> 0.063600056 | P37: =(_xlfn.XLOOKUP(Table1__3[[#This Row],[Campaign_Name]],Table3[Campaign_Name],Table3[Start_Date])) -> 45717 | Q37: =(_xlfn.XLOOKUP(Table1__3[[#This Row],[Campaign_Name]],Table3[Campaign_Name],Table3[End_Date])) -> 45747 | R37: =IF(Table1__3[[#This Row],[Date]] < Table1__3[[#This Row],[Start_Date]], "Before", IF(AND(Table1__3[[#This Row],[Date]] >= Table1__3[[#This Row],[Start_Date]], Table1__3[[#This Row],[Date]] <= Table1__3[[#This Row],[End_Date]]), "During", "After")) -> Before
A38: SP037 | B38: Twitter | C38: 45804 | D38: Story | E38: Explore the latest podcasts now. | F38: 4095 | G38: 385 | H38: 400 | I38: 45300 | J38: 31795 | K38: 80 | L38: #MusicForEveryone | M38: #NowPlaying | N38: ChillVibes | O38: =(F38+G38+H38)/I38 -> 0.10772627 | P38: =(_xlfn.XLOOKUP(Table1__3[[#This Row],[Campaign_Name]],Table3[Campaign_Name],Table3[Start_Date])) -> 45667 | Q38: =(_xlfn.XLOOKUP(Table1__3[[#This Row],[Campaign_Name]],Table3[Campaign_Name],Table3[End_Date])) -> 45698 | R38: =IF(Table1__3[[#This Row],[Date]] < Table1__3[[#This Row],[Start_Date]], "Before", IF(AND(Table1__3[[#This Row],[Date]] >= Table1__3[[#This Row],[Start_Date]], Table1__3[[#This Row],[Date]] <= Table1__3[[#This Row],[End_Date]]), "During", "After")) -> After
A39: SP038 | B39: Instagram | C39: 45545 | D39: Story | E39: New music just dropped. Hit play! | F39: 1230 | G39: 309 | H39: 207 | I39: 44629 | J39: 40699 | K39: 195 | L39: #NowPlaying | N39: Wrapped2024 | O39: =(F39+G39+H39)/I39 -> 0.039122544 | P39: =(_xlfn.XLOOKUP(Table1__3[[#This Row],[Campaign_Name]],Table3[Campaign_Name],Table3[Start_Date])) -> 45627 | Q39: =(_xlfn.XLOOKUP(Table1__3[[#This Row],[Campaign_Name]],Table3[Campaign_Name],Table3[End_Date])) -> 45657 | R39: =IF(Table1__3[[#This Row],[Date]] < Table1__3[[#This Row],[Start_Date]], "Before", IF(AND(Table1__3[[#This Row],[Date]] >= Table1__3[[#This Row],[Start_Date]], Table1__3[[#This Row],[Date]] <= Table1__3[[#This Row],[End_Date]]), "During", "After")) -> Before
A40: SP039 | B40: Instagram | C40: 45621 | D40: Text | E40: From pop to podcasts, itâ€™s all here. | F40: 1341 | G40: 472 | H40: 238 | I40: 51386 | J40: 51706 | K40: 133 | L40: #DiscoverWeekly | N40: IndieWave | O40: =(F40+G40+H40)/I40 -> 0.039913595 | P40: =(_xlfn.XLOOKUP(Table1__3[[#This Row],[Campaign_Name]],Table3[Campaign_Name],Table3[Start_Date])) -> 45717 | Q40: =(_xlfn.XLOOKUP(Table1__3[[#This Row],[Campaign_Name]],Table3[Campaign_Name],Table3[End_Date])) -> 45747 | R40: =IF(Table1__3[[#This Row],[Date]] < Table1__3[[#This Row],[Start_Date]], "Before", IF(AND(Table1__3[[#This Row],[Date]] >= Table1__3[[#This Row],[Start_Date]], Table1__3[[#This Row],[Date]] <= Table1__3[[#This Row],[End_Date]]), "During", "After")) -> Before
...

Sheet Engagement Summary
A1: Week_Start_Date | B1: Platform | C1: New_Followers | D1: Unfollows | E1: net followers grth | F1: Total_Followers | G1: Engagement_Rate | H1: Ad_Spend | I1: Weekly groth rate | J1: campign name | K1: ROI
A2: 45446 | B2: Instagram | C2: 1402 | D2: 68 | E2: =Table2[[#This Row],[New_Followers]]-Table2[[#This Row],[Unfollows]] -> 1334 | F2: 124562 | G2: 9.92 | H2: 23125 | I2: 0 | J2: {=IFERROR(INDEX(Table3[[#All],[Campaign_Name]],MATCH(1,(Table2[[#This Row],[Week_Start_Date]]>=Table3[[#All],[Start_Date]])*(Table2[[#This Row],[Week_Start_Date]]<=Table3[[#All],[End_Date]]),0)),"No Campign")} -> No Campign | K2: =Table2[[#This Row],[Engagement_Rate]]/Table2[[#This Row],[Ad_Spend]] -> 0.00042897297
A3: 45446 | B3: Twitter | C3: 995 | D3: 86 | E3: =Table2[[#This Row],[New_Followers]]-Table2[[#This Row],[Unfollows]] -> 909 | F3: 227958 | G3: 8.05 | H3: 22788 | I3: 0 | J3: {=IFERROR(INDEX(Table3[[#All],[Campaign_Name]],MATCH(1,(Table2[[#This Row],[Week_Start_Date]]>=Table3[[#All],[Start_Date]])*(Table2[[#This Row],[Week_Start_Date]]<=Table3[[#All],[End_Date]]),0)),"No Campign")} -> No Campign | K3: =Table2[[#This Row],[Engagement_Rate]]/Table2[[#This Row],[Ad_Spend]] -> 0.0003532561
A4: 45446 | B4: YouTube | C4: 1472 | D4: 296 | E4: =Table2[[#This Row],[New_Followers]]-Table2[[#This Row],[Unfollows]] -> 1176 | F4: 370242 | G4: 7.72 | H4: 7810 | I4: 0 | J4: {=IFERROR(INDEX(Table3[[#All],[Campaign_Name]],MATCH(1,(Table2[[#This Row],[Week_Start_Date]]>=Table3[[#All],[Start_Date]])*(Table2[[#This Row],[Week_Start_Date]]<=Table3[[#All],[End_Date]]),0)),"No Campign")} -> No Campign | K4: =Table2[[#This Row],[Engagement_Rate]]/Table2[[#This Row],[Ad_Spend]] -> 0.00098847631
A5: 45453 | B5: Instagram | C5: 1018 | D5: 90 | E5: =Table2[[#This Row],[New_Followers]]-Table2[[#This Row],[Unfollows]] -> 928 | F5: 92474 | G5: 9.4 | H5: 11966 | I5: =(Table2[[#This Row],[Total_Followers]]-F2)/F2 -> -0.25760665 | J5: {=IFERROR(INDEX(Table3[[#All],[Campaign_Name]],MATCH(1,(Table2[[#This Row],[Week_Start_Date]]>=Table3[[#All],[Start_Date]])*(Table2[[#This Row],[Week_Start_Date]]<=Table3[[#All],[End_Date]]),0)),"No Campign")} -> No Campign | K5: =Table2[[#This Row],[Engagement_Rate]]/Table2[[#This Row],[Ad_Spend]] -> 0.00078555908
A6: 45453 | B6: Twitter | C6: 1461 | D6: 64 | E6: =Table2[[#This Row],[New_Followers]]-Table2[[#This Row],[Unfollows]] -> 1397 | F6: 328902 | G6: 9.02 | H6: 26298 | I6: =(Table2[[#This Row],[Total_Followers]]-F3)/F3 -> 0.44281841 | J6: {=IFERROR(INDEX(Table3[[#All],[Campaign_Name]],MATCH(1,(Table2[[#This Row],[Week_Start_Date]]>=Table3[[#All],[Start_Date]])*(Table2[[#This Row],[Week_Start_Date]]<=Table3[[#All],[End_Date]]),0)),"No Campign")} -> No Campign | K6: =Table2[[#This Row],[Engagement_Rate]]/Table2[[#This Row],[Ad_Spend]] -> 0.00034299186
A7: 45453 | B7: YouTube | C7: 545 | D7: 93 | E7: =Table2[[#This Row],[New_Followers]]-Table2[[#This Row],[Unfollows]] -> 452 | F7: 391621 | G7: 9.96 | H7: 22029 | I7: =(Table2[[#This Row],[Total_Followers]]-F4)/F4 -> 0.057743314 | J7: {=IFERROR(INDEX(Table3[[#All],[Campaign_Name]],MATCH(1,(Table2[[#This Row],[Week_Start_Date]]>=Table3[[#All],[Start_Date]])*(Table2[[#This Row],[Week_Start_Date]]<=Table3[[#All],[End_Date]]),0)),"No Campign")} -> No Campign | K7: =Table2[[#This Row],[Engagement_Rate]]/Table2[[#This Row],[Ad_Spend]] -> 0.00045213128
A8: 45460 | B8: Instagram | C8: 881 | D8: 291 | E8: =Table2[[#This Row],[New_Followers]]-Table2[[#This Row],[Unfollows]] -> 590 | F8: 95885 | G8: 5.29 | H8: 12391 | I8: =(Table2[[#This Row],[Total_Followers]]-F5)/F5 -> 0.036886044 | J8: {=IFERROR(INDEX(Table3[[#All],[Campaign_Name]],MATCH(1,(Table2[[#This Row],[Week_Start_Date]]>=Table3[[#All],[Start_Date]])*(Table2[[#This Row],[Week_Start_Date]]<=Table3[[#All],[End_Date]]),0)),"No Campign")} -> SummerBeats | K8: =Table2[[#This Row],[Engagement_Rate]]/Table2[[#This Row],[Ad_Spend]] -> 0.00042692277
A9: 45460 | B9: Twitter | C9: 1414 | D9: 131 | E9: =Table2[[#This Row],[New_Followers]]-Table2[[#This Row],[Unfollows]] -> 1283 | F9: 245947 | G9: 8.3 | H9: 14477 | I9: =(Table2[[#This Row],[Total_Followers]]-F6)/F6 -> -0.25221799 | J9: {=IFERROR(INDEX(Table3[[#All],[Campaign_Name]],MATCH(1,(Table2[[#This Row],[Week_Start_Date]]>=Table3[[#All],[Start_Date]])*(Table2[[#This Row],[Week_Start_Date]]<=Table3[[#All],[End_Date]]),0)),"No Campign")} -> SummerBeats | K9: =Table2[[#This Row],[Engagement_Rate]]/Table2[[#This Row],[Ad_Spend]] -> 0.0005733232
A10: 45460 | B10: YouTube | C10: 1472 | D10: 170 | E10: =Table2[[#This Row],[New_Followers]]-Table2[[#This Row],[Unfollows]] -> 1302 | F10: 250428 | G10: 4.66 | H10: 25040 | I10: =(Table2[[#This Row],[Total_Followers]]-F7)/F7 -> -0.3605348 | J10: {=IFERROR(INDEX(Table3[[#All],[Campaign_Name]],MATCH(1,(Table2[[#This Row],[Week_Start_Date]]>=Table3[[#All],[Start_Date]])*(Table2[[#This Row],[Week_Start_Date]]<=Table3[[#All],[End_Date]]),0)),"No Campign")} -> SummerBeats | K10: =Table2[[#This Row],[Engagement_Rate]]/Table2[[#This Row],[Ad_Spend]] -> 0.00018610224
A11: 45467 | B11: Instagram | C11: 809 | D11: 197 | E11: =Table2[[#This Row],[New_Followers]]-Table2[[#This Row],[Unfollows]] -> 612 | F11: 87186 | G11: 9.48 | H11: 22619 | I11: =(Table2[[#This Row],[Total_Followers]]-F8)/F8 -> -0.090723262 | J11: {=IFERROR(INDEX(Table3[[#All],[Campaign_Name]],MATCH(1,(Table2[[#This Row],[Week_Start_Date]]>=Table3[[#All],[Start_Date]])*(Table2[[#This Row],[Week_Start_Date]]<=Table3[[#All],[End_Date]]),0)),"No Campign")} -> SummerBeats | K11: =Table2[[#This Row],[Engagement_Rate]]/Table2[[#This Row],[Ad_Spend]] -> 0.00041911667
A12: 45467 | B12: Twitter | C12: 1371 | D12: 250 | E12: =Table2[[#This Row],[New_Followers]]-Table2[[#This Row],[Unfollows]] -> 1121 | F12: 128620 | G12: 7.11 | H12: 12399 | I12: =(Table2[[#This Row],[Total_Followers]]-F9)/F9 -> -0.4770418 | J12: {=IFERROR(INDEX(Table3[[#All],[Campaign_Name]],MATCH(1,(Table2[[#This Row],[Week_Start_Date]]>=Table3[[#All],[Start_Date]])*(Table2[[#This Row],[Week_Start_Date]]<=Table3[[#All],[End_Date]]),0)),"No Campign")} -> SummerBeats | K12: =Table2[[#This Row],[Engagement_Rate]]/Table2[[#This Row],[Ad_Spend]] -> 0.00057343334
A13: 45467 | B13: YouTube | C13: 844 | D13: 144 | E13: =Table2[[#This Row],[New_Followers]]-Table2[[#This Row],[Unfollows]] -> 700 | F13: 126015 | G13: 9.65 | H13: 22456 | I13: =(Table2[[#This Row],[Total_Followers]]-F10)/F10 -> -0.49680148 | J13: {=IFERROR(INDEX(Table3[[#All],[Campaign_Name]],MATCH(1,(Table2[[#This Row],[Week_Start_Date]]>=Table3[[#All],[Start_Date]])*(Table2[[#This Row],[Week_Start_Date]]<=Table3[[#All],[End_Date]]),0)),"No Campign")} -> SummerBeats | K13: =Table2[[#This Row],[Engagement_Rate]]/Table2[[#This Row],[Ad_Spend]] -> 0.00042972925
A14: 45474 | B14: Instagram | C14: 786 | D14: 72 | E14: =Table2[[#This Row],[New_Followers]]-Table2[[#This Row],[Unfollows]] -> 714 | F14: 178615 | G14: 5.43 | H14: 19328 | I14: =(Table2[[#This Row],[Total_Followers]]-F11)/F11 -> 1.0486661 | J14: {=IFERROR(INDEX(Table3[[#All],[Campaign_Name]],MATCH(1,(Table2[[#This Row],[Week_Start_Date]]>=Table3[[#All],[Start_Date]])*(Table2[[#This Row],[Week_Start_Date]]<=Table3[[#All],[End_Date]]),0)),"No Campign")} -> SummerBeats | K14: =Table2[[#This Row],[Engagement_Rate]]/Table2[[#This Row],[Ad_Spend]] -> 0.00028093957
A15: 45474 | B15: Twitter | C15: 845 | D15: 250 | E15: =Table2[[#This Row],[New_Followers]]-Table2[[#This Row],[Unfollows]] -> 595 | F15: 218228 | G15: 4.52 | H15: 21107 | I15: =(Table2[[#This Row],[Total_Followers]]-F12)/F12 -> 0.69668792 | J15: {=IFERROR(INDEX(Table3[[#All],[Campaign_Name]],MATCH(1,(Table2[[#This Row],[Week_Start_Date]]>=Table3[[#All],[Start_Date]])*(Table2[[#This Row],[Week_Start_Date]]<=Table3[[#All],[End_Date]]),0)),"No Campign")} -> SummerBeats | K15: =Table2[[#This Row],[Engagement_Rate]]/Table2[[#This Row],[Ad_Spend]] -> 0.00021414697
A16: 45474 | B16: YouTube | C16: 1218 | D16: 101 | E16: =Table2[[#This Row],[New_Followers]]-Table2[[#This Row],[Unfollows]] -> 1117 | F16: 300397 | G16: 4.33 | H16: 12277 | I16: =(Table2[[#This Row],[Total_Followers]]-F13)/F13 -> 1.3838194 | J16: {=IFERROR(INDEX(Table3[[#All],[Campaign_Name]],MATCH(1,(Table2[[#This Row],[Week_Start_Date]]>=Table3[[#All],[Start_Date]])*(Table2[[#This Row],[Week_Start_Date]]<=Table3[[#All],[End_Date]]),0)),"No Campign")} -> SummerBeats | K16: =Table2[[#This Row],[Engagement_Rate]]/Table2[[#This Row],[Ad_Spend]] -> 0.00035269203
... A201: 45908 | B201: Twitter | C201: 860 | D201: 244 | E201: =Table2[[#This Row],[New_Followers]]-Table2[[#This Row],[Unfollows]] -> 616 | F201: 348686 | G201: 5.12 | H201: 11418 | I201: =(Table2[[#This Row],[Total_Followers]]-F198)/F198 -> 3.2385705 | J201: {=IFERROR(INDEX(Table3[[#All],[Campaign_Name]],MATCH(1,(Table2[[#This Row],[Week_Start_Date]]>=Table3[[#All],[Start_Date]])*(Table2[[#This Row],[Week_Start_Date]]<=Table3[[#All],[End_Date]]),0)),"No Campign")} -> No Campign | K201: =Table2[[#This Row],[Engagement_Rate]]/Table2[[#This Row],[Ad_Spend]] -> 0.00044841478

Sheet Campaign Metadata
A1: Campaign_Name | B1: Start_Date | C1: End_Date | D1: Objective | E1: Total_Budget | F1: Target_Platforms | G1: Primary_Hashtags
A2: SummerBeats | B2: 45458 | C2: 45488 | D2: Brand Awareness | E2: 175000 | F2: Instagram,YouTube | G2: #SpotifyWrapped,#MusicForEveryone
A3: Wrapped2024 | B3: 45627 | C3: 45657 | D3: Engagement | E3: 225000 | F3: Twitter,YouTube | G3: #SpotifyWrapped,#NowPlaying
A4: ChillVibes | B4: 45667 | C4: 45698 | D4: Product Launch | E4: 200000 | F4: Instagram,Twitter | G4: #ChillVibes,#SoundtrackOfLife
A5: IndieWave | B5: 45717 | C5: 45747 | D5: Traffic | E5: 160000 | F5: Facebook,Instagram | G5: #DiscoverWeekly,#IndieWave

Sheet Analysis done

Sheet Task 1
A1: Post ID | B1: Platform | C1: Column1 | D1: Content Type | E1: Post Text | F1: Likess | G1: Sharess | H1: Commentss | I1: Impressions | J1: Reach | K1: Clicks | L1: Hashtags Used.1 | M1: Hashtags Used.2 | N1: Campaign_Name | O1: Engagement Rate:
A2: SP001 | B2: Instagram | C2: 45781 | D2: Text | E2: Discover fresh beats on Spotify! | F2: 2414 | G2: 245 | H2: 137 | I2: 21181 | J2: 45292 | K2: 133 | L2: #SoundtrackOfLife | M2: #NowPlaying | N2: ChillVibes | O2: =(F2+H2+G2)/I2 -> 0.1320051
A3: SP002 | B3: Instagram | C3: 45689 | D3: Text | E3: Explore the latest podcasts now. | F3: 1934 | G3: 210 | H3: 393 | I3: 29129 | J3: 73287 | K3: 273 | L3: #DiscoverWeekly | N3: IndieWave | O3: =(F3+H3+G3)/I3 -> 0.087095335
A4: SP003 | B4: Twitter | C4: 45629 | D4: Story | E4: New music just dropped. Hit play! | F4: 3092 | G4: 177 | H4: 81 | I4: 47533 | J4: 29220 | K4: 121 | L4: #MusicForEveryone | M4: #NowPlaying | N4: ChillVibes | O4: =(F4+H4+G4)/I4 -> 0.070477353
A5: SP004 | B5: Instagram | C5: 45629 | D5: Text | E5: Wrapped is here! Relive your top tracks ðŸŽ§ | F5: 3173 | G5: 229 | H5: 197 | I5: 29604 | J5: 21809 | K5: 272 | L5: #SoundtrackOfLife | M5: #NowPlaying | N5: ChillVibes | O5: =(F5+H5+G5)/I5 -> 0.12157141
A6: SP005 | B6: YouTube | C6: 45388 | D6: Text | E6: Music that moves youâ€”only on Spotify. | F6: 2748 | G6: 145 | H6: 315 | I6: 24401 | J6: 61182 | K6: 200 | L6: #DiscoverWeekly | M6: #SpotifyWrapped | N6: IndieWave | O6: =(F6+H6+G6)/I6 -> 0.13147002
A7: SP006 | B7: YouTube | C7: 45456 | D7: Text | E7: Whatâ€™s your vibe today? #SpotifyHits | F7: 3882 | G7: 239 | H7: 275 | I7: 58748 | J7: 44646 | K7: 149 | L7: #DiscoverWeekly | M7: #SpotifyWrapped | N7: IndieWave | O7: =(F7+H7+G7)/I7 -> 0.074828079
A8: SP007 | B8: Twitter | C8: 45645 | D8: Story | E8: Get into the groove with our new drop! | F8: 4674 | G8: 409 | H8: 327 | I8: 20756 | J8: 63599 | K8: 212 | L8: #SoundtrackOfLife | M8: #NowPlaying | N8: ChillVibes | O8: =(F8+H8+G8)/I8 -> 0.26064752
A9: SP008 | B9: Twitter | C9: 45421 | D9: Story | E9: Wrapped is here! Relive your top tracks ðŸŽ§ | F9: 1428 | G9: 347 | H9: 67 | I9: 21148 | J9: 19712 | K9: 120 | L9: #DiscoverWeekly | M9: #MusicForEveryone | N9: ChillVibes | O9: =(F9+H9+G9)/I9 -> 0.087100435
A10: SP009 | B10: Twitter | C10: 45823 | D10: Text | E10: Top trending tracks updated daily! | F10: 4432 | G10: 223 | H10: 299 | I10: 59016 | J10: 21742 | K10: 171 | L10: #NowPlaying | N10: ChillVibes | O10: =(F10+H10+G10)/I10 -> 0.083943337
A11: SP010 | B11: Twitter | C11: 45630 | D11: Text | E11: Wrapped is here! Relive your top tracks ðŸŽ§ | F11: 2357 | G11: 274 | H11: 172 | I11: 21566 | J11: 66829 | K11: 284 | L11: #NowPlaying | N11: ChillVibes | O11: =(F11+H11+G11)/I11 -> 0.12997311
A12: SP011 | B12: Twitter | C12: 45357 | D12: Text | E12: Discover fresh beats on Spotify! | F12: 1971 | G12: 370 | H12: 306 | I12: 31316 | J12: 27897 | K12: 88 | L12: #SoundtrackOfLife | N12: IndieWave | O12: =(F12+H12+G12)/I12 -> 0.084525482
A13: SP012 | B13: Instagram | C13: 45426 | D13: Text | E13: Discover fresh beats on Spotify! | F13: 1485 | G13: 353 | H13: 244 | I13: 38419 | J13: 38556 | K13: 86 | L13: #SoundtrackOfLife | M13: #NowPlaying | N13: ChillVibes | O13: =(F13+H13+G13)/I13 -> 0.054191936
A14: SP013 | B14: Twitter | C14: 45826 | D14: Story | E14: Discover fresh beats on Spotify! | F14: 3956 | G14: 319 | H14: 61 | I14: 58162 | J14: 28720 | K14: 213 | L14: #MusicForEveryone | M14: #NowPlaying | N14: ChillVibes | O14: =(F14+H14+G14)/I14 -> 0.074550394
A15: SP014 | B15: Twitter | C15: 45573 | D15: Text | E15: From pop to podcasts, itâ€™s all here. | F15: 2460 | G15: 409 | H15: 253 | I15: 36702 | J15: 46122 | K15: 264 | L15: #NowPlaying | N15: ChillVibes | O15: =(F15+H15+G15)/I15 -> 0.085063484
A16: SP015 | B16: Twitter | C16: 45418 | D16: Text | E16: Your weekend playlist is waiting. | F16: 3476 | G16: 355 | H16: 396 | I16: 37492 | J16: 27285 | K16: 179 | L16: #NowPlaying | N16: ChillVibes | O16: =(F16+H16+G16)/I16 -> 0.11274405
A17: SP016 | B17: Twitter | C17: 45655 | D17: Story | E17: New music just dropped. Hit play! | F17: 4049 | G17: 377 | H17: 94 | I17: 48182 | J17: 42875 | K17: 172 | L17: #MusicForEveryone | M17: #NowPlaying | N17: ChillVibes | O17: =(F17+H17+G17)/I17 -> 0.093810967
A18: SP017 | B18: Twitter | C18: 45453 | D18: Text | E18: Whatâ€™s your vibe today? #SpotifyHits | F18: 1514 | G18: 164 | H18: 275 | I18: 41364 | J18: 44389 | K18: 83 | L18: #NowPlaying | N18: ChillVibes | O18: =(F18+H18+G18)/I18 -> 0.04721497
A19: SP018 | B19: Instagram | C19: 45325 | D19: Story | E19: Music that moves youâ€”only on Spotify. | F19: 4281 | G19: 101 | H19: 163 | I19: 32278 | J19: 53382 | K19: 235 | L19: #NowPlaying | N19: Wrapped2024 | O19: =(F19+H19+G19)/I19 -> 0.14080798 | AQ19: =SUMIF(B:B,"Instagram",O:O) -> 8.0807399
A20: SP019 | B20: YouTube | C20: 45458 | D20: Reel | E20: Get into the groove with our new drop! | F20: 1751 | G20: 143 | H20: 151 | I20: 31826 | J20: 47729 | K20: 95 | L20: #DiscoverWeekly | M20: #SoundtrackOfLife | N20: SummerBeats | O20: =(F20+H20+G20)/I20 -> 0.06425564 | AQ20: =SUMIF(B:B,"Twitter",O:O) -> 14.213122
A21: SP020 | B21: Instagram | C21: 45478 | D21: Text | E21: Your weekend playlist is waiting. | F21: 3753 | G21: 411 | H21: 308 | I21: 29138 | J21: 27678 | K21: 90 | L21: #DiscoverWeekly | N21: IndieWave | O21: =(F21+H21+G21)/I21 -> 0.15347656 | AQ21: =SUMIF(B:B,"YouTube",O:O) -> 5.5508115
A22: SP021 | B22: Instagram | C22: 45603 | D22: Story | E22: Wrapped is here! Relive your top tracks ðŸŽ§ | F22: 1678 | G22: 423 | H22: 323 | I22: 55668 | J22: 37945 | K22: 230 | L22: #NowPlaying | N22: Wrapped2024 | O22: =(F22+H22+G22)/I22 -> 0.043543867
A23: SP022 | B23: Instagram | C23: 45823 | D23: Text | E23: Whatâ€™s your vibe today? #SpotifyHits | F23: 4896 | G23: 466 | H23: 233 | I23: 28621 | J23: 34270 | K23: 84 | L23: #SoundtrackOfLife | M23: #NowPlaying | N23: ChillVibes | O23: =(F23+H23+G23)/I23 -> 0.19548583
A24: SP023 | B24: YouTube | C24: 45452 | D24: Reel | E24: From pop to podcasts, itâ€™s all here. | F24: 2786 | G24: 368 | H24: 208 | I24: 42000 | J24: 39967 | K24: 103 | L24: #DiscoverWeekly | M24: #SoundtrackOfLife | N24: SummerBeats | O24: =(F24+H24+G24)/I24 -> 0.080047619
A25: SP024 | B25: Twitter | C25: 45583 | D25: Text | E25: New music just dropped. Hit play! | F25: 2607 | G25: 379 | H25: 180 | I25: 28712 | J25: 61620 | K25: 174 | L25: #SoundtrackOfLife | N25: IndieWave | O25: =(F25+H25+G25)/I25 -> 0.11026748
A26: SP025 | B26: YouTube | C26: 45575 | D26: Reel | E26: From pop to podcasts, itâ€™s all here. | F26: 4013 | G26: 320 | H26: 92 | I26: 54605 | J26: 60169 | K26: 232 | L26: #DiscoverWeekly | M26: #SoundtrackOfLife | N26: SummerBeats | O26: =(F26+H26+G26)/I26 -> 0.081036535
A27: SP026 | B27: Twitter | C27: 45791 | D27: Story | E27: From pop to podcasts, itâ€™s all here. | F27: 2707 | G27: 103 | H27: 51 | I27: 55302 | J27: 18801 | K27: 147 | L27: #DiscoverWeekly | M27: #MusicForEveryone | N27: ChillVibes | O27: =(F27+H27+G27)/I27 -> 0.051734114
A28: SP027 | B28: Instagram | C28: 45625 | D28: Text | E28: Whatâ€™s your vibe today? #SpotifyHits | F28: 2824 | G28: 425 | H28: 274 | I28: 31004 | J28: 53488 | K28: 268 | L28: #SoundtrackOfLife | M28: #NowPlaying | N28: ChillVibes | O28: =(F28+H28+G28)/I28 -> 0.1136305
A29: SP028 | B29: YouTube | C29: 45356 | D29: Reel | E29: Explore the latest podcasts now. | F29: 3558 | G29: 314 | H29: 199 | I29: 49612 | J29: 53929 | K29: 206 | L29: #DiscoverWeekly | M29: #SoundtrackOfLife | N29: SummerBeats | O29: =(F29+H29+G29)/I29 -> 0.08205676
A30: SP029 | B30: Twitter | C30: 45734 | D30: Story | E30: Explore the latest podcasts now. | F30: 3418 | G30: 188 | H30: 387 | I30: 57431 | J30: 36933 | K30: 202 | L30: #MusicForEveryone | M30: #NowPlaying | N30: ChillVibes | O30: =(F30+H30+G30)/I30 -> 0.069526911
A31: SP030 | B31: Twitter | C31: 45773 | D31: Text | E31: Discover fresh beats on Spotify! | F31: 2411 | G31: 194 | H31: 168 | I31: 26665 | J31: 71699 | K31: 197 | L31: #NowPlaying | N31: ChillVibes | O31: =(F31+H31+G31)/I31 -> 0.103994
A32: SP031 | B32: Instagram | C32: 45658 | D32: Text | E32: New music just dropped. Hit play! | F32: 4036 | G32: 112 | H32: 382 | I32: 56284 | J32: 29440 | K32: 279 | L32: #SoundtrackOfLife | M32: #NowPlaying | N32: ChillVibes | O32: =(F32+H32+G32)/I32 -> 0.080484685
A33: SP032 | B33: Twitter | C33: 45419 | D33: Story | E33: Explore the latest podcasts now. | F33: 2776 | G33: 307 | H33: 178 | I33: 43365 | J33: 48408 | K33: 138 | L33: #SoundtrackOfLife | M33: #NowPlaying | N33: ChillVibes | O33: =(F33+H33+G33)/I33 -> 0.075198893
A34: SP033 | B34: Twitter | C34: 45574 | D34: Story | E34: Discover fresh beats on Spotify! | F34: 4929 | G34: 182 | H34: 95 | I34: 32181 | J34: 31084 | K34: 289 | L34: #DiscoverWeekly | M34: #MusicForEveryone | N34: ChillVibes | O34: =(F34+H34+G34)/I34 -> 0.16177247
A35: SP034 | B35: Instagram | C35: 45666 | D35: Text | E35: New music just dropped. Hit play! | F35: 1015 | G35: 366 | H35: 308 | I35: 38127 | J35: 63790 | K35: 287 | L35: #SoundtrackOfLife | M35: #NowPlaying | N35: ChillVibes | O35: =(F35+H35+G35)/I35 -> 0.044299315
A36: SP035 | B36: Twitter | C36: 45785 | D36: Story | E36: Your weekend playlist is waiting. | F36: 3316 | G36: 332 | H36: 268 | I36: 40095 | J36: 36913 | K36: 265 | L36: #MusicForEveryone | M36: #NowPlaying | N36: ChillVibes | O36: =(F36+H36+G36)/I36 -> 0.097668038
A37: SP036 | B37: Instagram | C37: 45416 | D37: Text | E37: Wrapped is here! Relive your top tracks ðŸŽ§ | F37: 2274 | G37: 243 | H37: 222 | I37: 43066 | J37: 59174 | K37: 80 | L37: #DiscoverWeekly | N37: IndieWave | O37: =(F37+H37+G37)/I37 -> 0.063600056
A38: SP037 | B38: Twitter | C38: 45804 | D38: Story | E38: Explore the latest podcasts now. | F38: 4095 | G38: 385 | H38: 400 | I38: 45300 | J38: 31795 | K38: 80 | L38: #MusicForEveryone | M38: #NowPlaying | N38: ChillVibes | O38: =(F38+H38+G38)/I38 -> 0.10772627
A39: SP038 | B39: Instagram | C39: 45545 | D39: Story | E39: New music just dropped. Hit play! | F39: 1230 | G39: 309 | H39: 207 | I39: 44629 | J39: 40699 | K39: 195 | L39: #NowPlaying | N39: Wrapped2024 | O39: =(F39+H39+G39)/I39 -> 0.039122544
A40: SP039 | B40: Instagram | C40: 45621 | D40: Text | E40: From pop to podcasts, itâ€™s all here. | F40: 1341 | G40: 472 | H40: 238 | I40: 51386 | J40: 51706 | K40: 133 | L40: #DiscoverWeekly | N40: IndieWave | O40: =(F40+H40+G40)/I40 -> 0.039913595
...

Sheet TASK2
E6: Task 2: Engagement Analysis | L6: Identify Top 10 posts by engagement rate
N7: Row Labels | O7: Sum of Engagement Rate:
N8: SP007 | O8: 0.26064752
G9: Engagement Rate per platform | N9: SP022 | O9: 0.19548583
E10: Row Labels | F10: Sum of Likes | G10: Sum of Shares | H10: Sum of Comments | I10: Sum of Impressions | J10: Sum of ENGAGEMENT RATE | N10: SP050 | O10: 0.20241061
E11: Instagram | F11: 251473 | G11: 29285 | H11: 20818 | I11: 3553489 | J11: 0.29020775 | N11: SP068 | O11: 0.18517979
E12: Twitter | F12: 450295 | G12: 45498 | H12: 31577 | I12: 6138949 | J12: 0.51044312 | N12: SP106 | O12: 0.23193025
E13: YouTube | F13: 195407 | G13: 18618 | H13: 14671 | I13: 2777994 | J13: 0.19934913 | N13: SP136 | O13: 0.18723442
E14: Grand Total | F14: 897175 | G14: 93401 | H14: 67066 | I14: 12470432 | J14: 1 | N14: SP157 | O14: 0.19390492
N15: SP186 | O15: 0.22967525
N16: SP248 | O16: 0.19261223
N17: SP279 | O17: 0.2044586
N18: Grand Total | O18: 2.0835394
E19: Total Likes, Shares, Comments by Content type and Platform
F20: Row Labels | G20: Sum of Likess | H20: Sum of Sharess | I20: Sum of Commentss
F21: Instagram | G21: 251473 | H21: 29285 | I21: 20818
F22: Story | G22: 61815 | H22: 7993 | I22: 5656
F23: Text | G23: 189658 | H23: 21292 | I23: 15162
F24: Twitter | G24: 450295 | H24: 45498 | I24: 31577
F25: Story | G25: 272103 | H25: 26494 | I25: 18442
F26: Text | G26: 178192 | H26: 19004 | I26: 13135
F27: YouTube | G27: 195407 | H27: 18618 | I27: 14671
F28: Reel | G28: 89871 | H28: 9086 | I28: 6826
F29: Text | G29: 105536 | H29: 9532 | I29: 7845
F30: Grand Total | G30: 897175 | H30: 93401 | I30: 67066
G35: Average Clicks per post by Hashtag
G36: #Hastags | H36: Avg Clicks
G37: #NowPlaying | H37: {=AVERAGE( _xlfn._xlws.FILTER( Table1__3[Clicks], ( (Table1__3[Hashtags Used.1] = G37) + (Table1__3[Hashtags Used.2]= G37) ) > 0 ) )} -> 186.72028
G38: #DiscoverWeekly | H38: {=AVERAGE( _xlfn._xlws.FILTER( Table1__3[Clicks], ( (Table1__3[Hashtags Used.1] = G38) + (Table1__3[Hashtags Used.2]= G38) ) > 0 ) )} -> 197.16923
G39: #SoundtrackOfLife | H39: {=AVERAGE( _xlfn._xlws.FILTER( Table1__3[Clicks], ( (Table1__3[Hashtags Used.1] = G39) + (Table1__3[Hashtags Used.2]= G39) ) > 0 ) )} -> 192.45872
G40: #MusicForEveryone | H40: {=AVERAGE( _xlfn._xlws.FILTER( Table1__3[Clicks], ( (Table1__3[Hashtags Used.1] = G40) + (Table1__3[Hashtags Used.2]= G40) ) > 0 ) )} -> 183.47761
G41: #SpotifyWrapped | H41: {=AVERAGE( _xlfn._xlws.FILTER( Table1__3[Clicks], ( (Table1__3[Hashtags Used.1] = G41) + (Table1__3[Hashtags Used.2]= G41) ) > 0 ) )} -> 208.47059
M47: Highlight Top-performing hashtags using ranking formulas
M48: Rank | N48: Hastags | O48: Avg Reach
M49: =_xlfn.RANK.EQ(O49, $O$49:$O$53, 0) -> 3 | N49: #NowPlaying | O49: {=AVERAGE( _xlfn._xlws.FILTER( Table1__3[Reach], ( (Table1__3[Hashtags Used.1] = TASK2!N49) + (Table1__3[Hashtags Used.2]= TASK2!N49) ) > 0 ) )} -> 44969.448
M50: =_xlfn.RANK.EQ(O50, $O$49:$O$53, 0) -> 2 | N50: #DiscoverWeekly | O50: {=AVERAGE( _xlfn._xlws.FILTER( Table1__3[Reach], ( (Table1__3[Hashtags Used.1] = TASK2!N50) + (Table1__3[Hashtags Used.2]= TASK2!N50) ) > 0 ) )} -> 45124.3
M51: =_xlfn.RANK.EQ(O51, $O$49:$O$53, 0) -> 1 | N51: #SoundtrackOfLife | O51: {=AVERAGE( _xlfn._xlws.FILTER( Table1__3[Reach], ( (Table1__3[Hashtags Used.1] = TASK2!N51) + (Table1__3[Hashtags Used.2]= TASK2!N51) ) > 0 ) )} -> 45273.349
M52: =_xlfn.RANK.EQ(O52, $O$49:$O$53, 0) -> 5 | N52: #MusicForEveryone | O52: {=AVERAGE( _xlfn._xlws.FILTER( Table1__3[Reach], ( (Table1__3[Hashtags Used.1] = TASK2!N52) + (Table1__3[Hashtags Used.2]= TASK2!N52) ) > 0 ) )} -> 42321.403
M53: =_xlfn.RANK.EQ(O53, $O$49:$O$53, 0) -> 4 | N53: #SpotifyWrapped | O53: {=AVERAGE( _xlfn._xlws.FILTER( Table1__3[Reach], ( (Table1__3[Hashtags Used.1] = TASK2!N53) + (Table1__3[Hashtags Used.2]= TASK2!N53) ) > 0 ) )} -> 44703.088

Sheet TASK3
E6: Task 3: Platform Performance Analysis
L10: Platform | M10: YouTube
D11: Twitter platform yields highest engagement | K11: Compare weekly follower growth rates across platforms
E12: Row Labels | F12: Sum of Engagement Rate: | L12: Row Labels | M12: Sum of Total_Followers | N12: Sum of Weekly groth rate
E13: Instagram | F13: 0.29020775 | L13: 3/3/2025 - 3/9/2025 | M13: 274567 | N13: 1.1427974
E14: Twitter | F14: 0.51044312 | L14: 3/10/2025 - 3/16/2025 | M14: 340750 | N14: -1.0774778
E15: YouTube | F15: 0.19934913 | L15: 3/17/2025 - 3/23/2025 | M15: 263488 | N15: 1.0135386
E16: Grand Total | F16: 1 | L16: 3/24/2025 - 3/30/2025 | M16: 397607 | N16: -2.2753054 | P16: Average Weekly Growth Rate of Platforms
L17: 3/31/2025 - 4/6/2025 | M17: 202234 | N17: 2.1964471 | P17: Instagram | Q17: Twitter | R17: YouTube
L18: Grand Total | M18: 1478646 | N18: 1 | P18: =AVERAGEIF('Engagement Summary'!B:B, "Instagram",Table2[Weekly groth rate] ) -> 0.31276378 | Q18: =AVERAGEIF('Engagement Summary'!B:B, "TWITTER",Table2[Weekly groth rate] ) -> 0.14875327 | R18: =AVERAGEIF('Engagement Summary'!B:B, "yOUTUBE",Table2[Weekly groth rate] ) -> #DIV/0!
C20: Visualize Ad Spend vs. Engagement using charts
D21: Row Labels | E21: Sum of Ad_Spend | F21: Sum of Engagement_Rate
D22: Instagram | E22: 1035942 | F22: 432.7
D23: Twitter | E23: 1114204 | F23: 461.34
D24: YouTube | E24: 1065782 | F24: 443.45
D25: Grand Total | E25: 3215928 | F25: 1337.49
B44: Recommend focusing on 1–2 platforms or continuing multi-platform justify with data
F46: Platform | G46: Ad_Spend
F47: Instagram | G47: =SUMIF('Engagement Summary'!B:B,"Instagram",'Engagement Summary'!H:H) -> 1030447
C48: Row Labels | D48: Sum of Engagement_Rate | F48: Twitter | G48: =SUMIF('Engagement Summary'!B:B,"Twitter",'Engagement Summary'!H:H) -> 1114204
C49: Instagram | D49: 0.32351644 | F49: Youtube | G49: =SUMIF('Engagement Summary'!B:B,"Youtube",'Engagement Summary'!H:H) -> 1065782
C50: Twitter | D50: 0.34492968 | F50: Grand Total | G50: =SUM(G47,G48,G49) -> 3210433
C51: YouTube | D51: 0.33155388
C52: Grand Total | D52: 1 | F52: Row Labels | G52: Sum of Total_Followers
F53: Instagram | G53: 15642297
F54: Twitter | G54: 14575123
F55: YouTube | G55: 16284387
F56: Grand Total | G56: 46501807
F64: insta+twitter engagement rate
F65: =SUM(GETPIVOTDATA("Engagement Rate t",$C$47,"Platform","Instagram"),GETPIVOTDATA("Engagement Rate t",$C$47,"Platform","Twitter")) -> #REF!

Sheet Task 4
C2: Most frequent hashtags and average engagement for each | N2: Text, Story,Reel performance across platforms
N4: Average of Impressions | O4: Column Labels
N5: Row Labels | O5: Reel | P5: Story | Q5: Text | R5: Grand Total
D6: All Hastags | E6: # Usage Count | F6: Engagement Rate Avg | N6: Instagram | P6: 37626.348 | Q6: 40728.53 | R6: 39926.843
D7: #NowPlaying | E7: =COUNTIF(Table1__3[[Hashtags Used.1]:[Hashtags Used.2]],D7) -> 143 | F7: {=AVERAGE(_xlfn._xlws.FILTER(Posts!O:O,(Posts!L:L=Table9[[#This Row],[All Hastags ]])+(Posts!M:M=Table9[[#This Row],[All Hastags ]])))} -> 0.098567431 | N7: Twitter | P7: 42215.747 | Q7: 40429.164 | R7: 41479.385
D8: #DiscoverWeekly | E8: =COUNTIF(Table1__3[[Hashtags Used.1]:[Hashtags Used.2]],D8) -> 130 | F8: {=AVERAGE(_xlfn._xlws.FILTER(Posts!O:O,(Posts!L:L=Table9[[#This Row],[All Hastags ]])+(Posts!M:M=Table9[[#This Row],[All Hastags ]])))} -> 0.087606633 | N8: YouTube | O8: 42546.655 | Q8: 45415.912 | R8: 44095.143
D9: #SoundtrackOfLife | E9: =COUNTIF(Table1__3[[Hashtags Used.1]:[Hashtags Used.2]],D9) -> 109 | F9: {=AVERAGE(_xlfn._xlws.FILTER(Posts!O:O,(Posts!L:L=Table9[[#This Row],[All Hastags ]])+(Posts!M:M=Table9[[#This Row],[All Hastags ]])))} -> 0.09444867 | N9: Grand Total | O9: 42546.655 | P9: 41256.145 | Q9: 41604.988 | R9: 41568.107
D10: #MusicForEveryone | E10: =COUNTIF(Table1__3[[Hashtags Used.1]:[Hashtags Used.2]],D10) -> 67 | F10: {=AVERAGE(_xlfn._xlws.FILTER(Posts!O:O,(Posts!L:L=Table9[[#This Row],[All Hastags ]])+(Posts!M:M=Table9[[#This Row],[All Hastags ]])))} -> 0.089057449
D11: #SpotifyWrapped | E11: =COUNTIF(Table1__3[[Hashtags Used.1]:[Hashtags Used.2]],D11) -> 34 | F11: {=AVERAGE(_xlfn._xlws.FILTER(Posts!O:O,(Posts!L:L=Table9[[#This Row],[All Hastags ]])+(Posts!M:M=Table9[[#This Row],[All Hastags ]])))} -> 0.086403291
D14: Most used hashtag # | E14: =INDEX(Table9[[All Hastags ]],MATCH(MAX(Table9['# Usage Count]),Table9['# Usage Count],0)) -> #NowPlaying
N22: Optimal Content Type-Platform Combinations

Sheet Task 5
E5: Compute: Total & average impressions, likes, clicks per campaign
F7: Row Labels | G7: Average of Likess | H7: Average of Clicks | I7: Average of Impressions | J7: Sum of Likess | K7: Sum of Clicks | L7: Sum of Impressions
F8: ChillVibes | G8: 3058.6623 | H8: 186.41558 | I8: 41116.026 | J8: 471034 | K8: 28708 | L8: 6331868
F9: IndieWave | G9: 2919.734 | H9: 199.11702 | I9: 42971.33 | J9: 274455 | K9: 18717 | L9: 4039305
F10: SummerBeats | G10: 3099 | H10: 191.62069 | I10: 42546.655 | J10: 89871 | K10: 5557 | L10: 1233853
F11: Wrapped2024 | G11: 2687.6087 | H11: 200.6087 | I11: 37626.348 | J11: 61815 | K11: 4614 | L11: 865406
F12: Grand Total | G12: 2990.5833 | H12: 191.98667 | I12: 41568.107 | J12: 897175 | K12: 57596 | L12: 12470432
D18: Compute: Engagement uplift during vs. before campaign
D21: Average of ENGAGEMENT RATE | E21: Column Labels
D22: Row Labels | E22: ChillVibes | F22: IndieWave | G22: SummerBeats | H22: Wrapped2024 | I22: Grand Total | K22: =(GETPIVOTDATA("ENGAGEMENT RATE",$D$21,"status of cmpign","During")-GETPIVOTDATA("ENGAGEMENT RATE",$D$21,"status of cmpign","Before"))/GETPIVOTDATA("ENGAGEMENT RATE",$D$21,"status of cmpign","Before") -> 0.23348151
D23: After | E23: 0.096937629 | F23: 0.085210186 | G23: 0.083934545 | H23: 0.1047681 | I23: 0.093968206
D24: Before | E24: 0.092728032 | F24: 0.086673079 | G24: 0.097485783 | H24: 0.08707445 | I24: 0.090475289
D25: During | E25: 0.1208618 | F25: 0.11095871 | G25: 0.078574757 | H25: 0.095604953 | I25: 0.1115996
D26: Grand Total | E26: 0.095830989 | F26: 0.088052036 | G26: 0.090106882 | H26: 0.095509124 | I26: 0.092815577
D28: Engagement uplift during vs. before campaign
D29: Hastags | E29: uplift
